# 错误处理和资源管理
## 错误处理和资源管理
### defer调用
很多现代的编程语言中都有 defer 关键字，Go 语言的 defer 会在当前函数返回前执行传入的函数，它会经常被用于关闭文件描述符、关闭数据库连接以及解锁资源。

defer 调用：确保调用在函数结束时发生：

实例：

```
func do06() {
	for i := 0; i < 3; i++ {
		defer fmt.Println("defer: line ", i)
	}
	fmt.Println("defer: line  3")
}

func main() {

	fmt.Println("this is chapter 4")
	do06()

}

```

输出：

```
this is chapter 4
defer: line  3
defer: line  2
defer: line  1
defer: line  0
```


## 错误处理概念
一般会对函数添加一些出错处理，知道的就按照自己直到的方式处理，不知道的类型就可以按照默认的方式处理，例如直接通过panic来处理。

实例：

```
package main

import (
	"bufio"
	"fmt"
	"os"
)

func writeFile(filename string) {
	fmt.Println("test writeFile")
	file, err := os.OpenFile(filename, os.O_EXCL|os.O_RDWR|os.O_CREATE, 0666)
	// err = errors.New("this is an unknown err")
	if err != nil {
		if pathErr, ok := err.(*os.PathError); !ok {
			panic(err)
		} else {
			fmt.Printf("%s, %s, %s\n", pathErr.Op, pathErr.Path, pathErr.Err)
		}
		return
	}
	defer file.Close()
	writer := bufio.NewWriter(file)
	defer writer.Flush()
	for i := 0; i < 20; i++ {
		fmt.Fprintln(writer, i)
	}
}

func main() {
	writeFile("8.2.txt")
}
```
输出：

```
test writeFile
open, 8.2.txt, file exists
```
当8.2.txt存在的时候，再次创建就会报错，当新建一个 errors.New 后，就会出现不知道的 error类型，从而触发panic；

## 服务器统一出错处理
使用 http 来读取文件，并设置了多种不同的出错处理方式；
案例中的 http 如果出错了，并不会直接退出, 其原因为其内部使用了recover：

实例：

```
package filelisting

import (
	"io/ioutil"
	"net/http"
	"os"
)

func HandleFileList(writer http.ResponseWriter, request *http.Request) error {
	path := request.URL.Path[len("/list/"):]
	file, err := os.Open(path)
	if err != nil {
		// panic(err)
		// http.Error(writer, err.Error(), http.StatusInternalServerError)
		return err
	}
	defer file.Close()
	all, err := ioutil.ReadAll(file)
	if err != nil {
		return err
	}
	writer.Write(all)
	return nil
}



type appHandler func(writer http.ResponseWriter, request *http.Request) error


//错误的统一处理
func errWarpper(handler appHandler) func(w http.ResponseWriter, r *http.Request) {
	return func(writer http.ResponseWriter,
		request *http.Request) {
		err := handler(writer, request)
		if err != nil {
			log.Warn("error occurred handling request: %s", err.Error())
			code := http.StatusOK
			switch {
			case os.IsNotExist(err):
				code = http.StatusNotFound
				//http.Error(writer, http.StatusText(http.StatusNotFound), http.StatusNotFound)
			case os.IsPermission(err):
				code = http.StatusForbidden
			default:
				code = http.StatusInternalServerError
			}
			http.Error(writer, http.StatusText(code), code)
		}
	}
}

func main() {
	http.HandleFunc("/list/", errWarpper(filelisting.HandleFileList))
	err := http.ListenAndServe(":9090", nil)
	if err != nil {
		panic(err)
	}

}

```

## panic和recover
### panic(尽量少用)：

一般而言，当宕机发生时，程序会中断运行，并立即执行在该 goroutine（可以先理解成线程）中被延迟的函数（defer 机制），随后，程序崩溃并输出日志信息，日志信息包括 panic value 和函数调用的堆栈跟踪信息，panic value 通常是某种错误信息。

- 停止当前函数执行；
- 一直向上返回，执行每一层的defer；
- 如果没有遇见recover，程序退出；

实例：

Go语言可以在程序中手动触发宕机，让程序崩溃，这样开发者可以及时地发现错误，同时减少可能的损失。

```
package main
func main() {
    panic("crash")
}
```
输出：

```
panic: crash

goroutine 1 [running]:
main.main()
    D:/code/main.go:4 +0x40
exit status 2
```

### 触发延迟执行语句

当 panic() 触发的宕机发生时，panic() 后面的代码将不会被运行，但是在 panic() 函数前面已经运行过的 defer 语句依然会在宕机发生时发生作用，参考下面代码：


```
package main
import "fmt"
func main() {
    defer fmt.Println("宕机后要做的事情1")
    defer fmt.Println("宕机后要做的事情2")
    panic("宕机")
}
```

输出：

```
宕机后要做的事情2
宕机后要做的事情1
panic: 宕机

goroutine 1 [running]:
main.main()
    D:/code/main.go:8 +0xf8
exit status 2
```



###  recover：
 
 Recover 是一个Go语言的内建函数，可以让进入宕机流程中的 goroutine 恢复过来，recover 仅在延迟函数 defer 中有效，在正常的执行过程中，调用 recover 会返回 nil 并且没有其他任何效果，如果当前的 goroutine 陷入恐慌，调用 recover 可以捕获到 panic 的输入值，并且恢复正常的执行。
- 仅在defer调用中使用；
- 获取 panic 的值；
- 如果无法处理，可以重新 panic

实例：

```
package main
import (
    "fmt"
    "runtime"
)
// 崩溃时需要传递的上下文信息
type panicContext struct {
    function string // 所在函数
}
// 保护方式允许一个函数
func ProtectRun(entry func()) {
    // 延迟处理的函数
    defer func() {
        // 发生宕机时，获取panic传递的上下文并打印
        err := recover()
        switch err.(type) {
        case runtime.Error: // 运行时错误
            fmt.Println("runtime error:", err)
        default: // 非运行时错误
            fmt.Println("error:", err)
        }
    }()
    entry()
}
func main() {
    fmt.Println("运行前")
    // 允许一段手动触发的错误
    ProtectRun(func() {
        fmt.Println("手动宕机前")
        // 使用panic传递上下文
        panic(&panicContext{
            "手动触发panic",
        })
        fmt.Println("手动宕机后")
    })
    // 故意造成空指针访问错误
    ProtectRun(func() {
        fmt.Println("赋值宕机前")
        var a *int
        *a = 1
        fmt.Println("赋值宕机后")
    })
    fmt.Println("运行后")
}
```

输出:


```
运行前
手动宕机前
error: &{手动触发panic}
赋值宕机前
runtime error: runtime error: invalid memory address or nil pointer dereference
运行后
```

### panic 和 recover 的关系

panic 和 recover 的组合有如下特性：
- 有 panic 没 recover，程序宕机。
- 有 panic 也有 recover，程序不会宕机，执行完对应的 defer 后，从宕机点退出当前函数后继续执行。


实例：

```
package main

import (
	"errors"
	"fmt"
)

func myRecover() {
	r := recover()
	if r == nil {
		fmt.Print("nothing to recover")
		return
	}
	if err, ok := r.(error); ok {
		fmt.Println("error occurred:", err)
	} else {
		panic(fmt.Sprintf("I don't know what to do $v", r))
	}
}
func tryRecover() {
	//defer func() {此处也可以直接将上述函数中的内放在一个匿名函数中}()
	defer myRecover()
	panic(errors.New("this is an error"))
}

func tryRecover2() {
	defer myRecover()
	b := 0
	a := 5 / b
	fmt.Print(a)
}
func tryRecover3() {
	defer myRecover()
	panic(123)
}
func main() {
	tryRecover()
	tryRecover2()
	tryRecover3()
}

```
输出：

```
error occurred: this is an error
error occurred: runtime error: integer divide by zero
panic: 123 [recovered]
        panic: I don't know what to do $v%!(EXTRA int=123)

goroutine 1 [running]:
......
Process finished with exit code 2
```

